[2025-07-05T11:49:39.177+0000] {local_task_job_runner.py:120} INFO - ::group::Pre task execution logs
[2025-07-05T11:49:39.190+0000] {taskinstance.py:2076} INFO - Dependencies all met for dep_context=non-requeueable deps ti=<TaskInstance: practice_etl_pipeline.extract manual__2025-07-05T11:49:35.131773+00:00 [queued]>
[2025-07-05T11:49:39.194+0000] {taskinstance.py:2076} INFO - Dependencies all met for dep_context=requeueable deps ti=<TaskInstance: practice_etl_pipeline.extract manual__2025-07-05T11:49:35.131773+00:00 [queued]>
[2025-07-05T11:49:39.195+0000] {taskinstance.py:2306} INFO - Starting attempt 1 of 1
[2025-07-05T11:49:39.202+0000] {taskinstance.py:2330} INFO - Executing <Task(PythonOperator): extract> on 2025-07-05 11:49:35.131773+00:00
[2025-07-05T11:49:39.207+0000] {clientserver.py:570} INFO - Closing down clientserver connection
[2025-07-05T11:49:39.207+0000] {warnings.py:112} WARNING - /home/***/.local/lib/python3.12/site-packages/***/task/task_runner/standard_task_runner.py:61: DeprecationWarning: This process (pid=3221) is multi-threaded, use of fork() may lead to deadlocks in the child.
  pid = os.fork()

[2025-07-05T11:49:39.208+0000] {standard_task_runner.py:63} INFO - Started process 3390 to run task
[2025-07-05T11:49:39.210+0000] {standard_task_runner.py:90} INFO - Running: ['***', 'tasks', 'run', 'practice_etl_pipeline', 'extract', 'manual__2025-07-05T11:49:35.131773+00:00', '--job-id', '22', '--raw', '--subdir', 'DAGS_FOLDER/main.py', '--cfg-path', '/tmp/tmpc6fe_tzy']
[2025-07-05T11:49:39.212+0000] {standard_task_runner.py:91} INFO - Job 22: Subtask extract
[2025-07-05T11:49:39.253+0000] {task_command.py:426} INFO - Running <TaskInstance: practice_etl_pipeline.extract manual__2025-07-05T11:49:35.131773+00:00 [running]> on host 6802b12b52ea
[2025-07-05T11:49:39.304+0000] {taskinstance.py:2648} INFO - Exporting env vars: AIRFLOW_CTX_DAG_OWNER='***' AIRFLOW_CTX_DAG_ID='practice_etl_pipeline' AIRFLOW_CTX_TASK_ID='extract' AIRFLOW_CTX_EXECUTION_DATE='2025-07-05T11:49:35.131773+00:00' AIRFLOW_CTX_TRY_NUMBER='1' AIRFLOW_CTX_DAG_RUN_ID='manual__2025-07-05T11:49:35.131773+00:00'
[2025-07-05T11:49:39.305+0000] {taskinstance.py:430} INFO - ::endgroup::
[2025-07-05T11:49:39.312+0000] {taskinstance.py:441} INFO - ::group::Post task execution logs
[2025-07-05T11:49:39.312+0000] {taskinstance.py:2905} ERROR - Task failed with exception
Traceback (most recent call last):
  File "/home/airflow/.local/lib/python3.12/site-packages/airflow/models/taskinstance.py", line 465, in _execute_task
    result = _execute_callable(context=context, **execute_callable_kwargs)
             ^^^^^^^^^^^^^^^^^^^^^^^^^^^^^^^^^^^^^^^^^^^^^^^^^^^^^^^^^^^^^
  File "/home/airflow/.local/lib/python3.12/site-packages/airflow/models/taskinstance.py", line 432, in _execute_callable
    return execute_callable(context=context, **execute_callable_kwargs)
           ^^^^^^^^^^^^^^^^^^^^^^^^^^^^^^^^^^^^^^^^^^^^^^^^^^^^^^^^^^^^
  File "/home/airflow/.local/lib/python3.12/site-packages/airflow/models/baseoperator.py", line 401, in wrapper
    return func(self, *args, **kwargs)
           ^^^^^^^^^^^^^^^^^^^^^^^^^^^
  File "/home/airflow/.local/lib/python3.12/site-packages/airflow/operators/python.py", line 235, in execute
    return_value = self.execute_callable()
                   ^^^^^^^^^^^^^^^^^^^^^^^
  File "/home/airflow/.local/lib/python3.12/site-packages/airflow/operators/python.py", line 252, in execute_callable
    return self.python_callable(*self.op_args, **self.op_kwargs)
           ^^^^^^^^^^^^^^^^^^^^^^^^^^^^^^^^^^^^^^^^^^^^^^^^^^^^^
  File "/opt/airflow/dags/main.py", line 91, in extract
    filenames = [f for f in os.listdir(CSV_PATH) if f.endswith('.csv')]
                            ^^^^^^^^^^^^^^^^^^^^
FileNotFoundError: [Errno 2] No such file or directory: '../files/'
[2025-07-05T11:49:39.318+0000] {taskinstance.py:1206} INFO - Marking task as FAILED. dag_id=practice_etl_pipeline, task_id=extract, run_id=manual__2025-07-05T11:49:35.131773+00:00, execution_date=20250705T114935, start_date=20250705T114939, end_date=20250705T114939
[2025-07-05T11:49:39.326+0000] {standard_task_runner.py:110} ERROR - Failed to execute job 22 for task extract ([Errno 2] No such file or directory: '../files/'; 3390)
[2025-07-05T11:49:39.345+0000] {local_task_job_runner.py:240} INFO - Task exited with return code 1
[2025-07-05T11:49:39.351+0000] {local_task_job_runner.py:222} INFO - ::endgroup::
