[2025-07-05T12:09:28.546+0000] {local_task_job_runner.py:120} INFO - ::group::Pre task execution logs
[2025-07-05T12:09:28.557+0000] {taskinstance.py:2076} INFO - Dependencies all met for dep_context=non-requeueable deps ti=<TaskInstance: practice_etl_pipeline.transform_and_load manual__2025-07-05T12:09:20.312632+00:00 [queued]>
[2025-07-05T12:09:28.562+0000] {taskinstance.py:2076} INFO - Dependencies all met for dep_context=requeueable deps ti=<TaskInstance: practice_etl_pipeline.transform_and_load manual__2025-07-05T12:09:20.312632+00:00 [queued]>
[2025-07-05T12:09:28.562+0000] {taskinstance.py:2306} INFO - Starting attempt 1 of 1
[2025-07-05T12:09:28.570+0000] {taskinstance.py:2330} INFO - Executing <Task(PythonOperator): transform_and_load> on 2025-07-05 12:09:20.312632+00:00
[2025-07-05T12:09:28.574+0000] {clientserver.py:570} INFO - Closing down clientserver connection
[2025-07-05T12:09:28.574+0000] {warnings.py:112} WARNING - /home/***/.local/lib/python3.12/site-packages/***/task/task_runner/standard_task_runner.py:61: DeprecationWarning: This process (pid=8880) is multi-threaded, use of fork() may lead to deadlocks in the child.
  pid = os.fork()

[2025-07-05T12:09:28.575+0000] {standard_task_runner.py:63} INFO - Started process 9052 to run task
[2025-07-05T12:09:28.576+0000] {standard_task_runner.py:90} INFO - Running: ['***', 'tasks', 'run', 'practice_etl_pipeline', 'transform_and_load', 'manual__2025-07-05T12:09:20.312632+00:00', '--job-id', '46', '--raw', '--subdir', 'DAGS_FOLDER/main.py', '--cfg-path', '/tmp/tmpbkvepfhg']
[2025-07-05T12:09:28.578+0000] {standard_task_runner.py:91} INFO - Job 46: Subtask transform_and_load
[2025-07-05T12:09:28.611+0000] {task_command.py:426} INFO - Running <TaskInstance: practice_etl_pipeline.transform_and_load manual__2025-07-05T12:09:20.312632+00:00 [running]> on host 6802b12b52ea
[2025-07-05T12:09:28.655+0000] {taskinstance.py:2648} INFO - Exporting env vars: AIRFLOW_CTX_DAG_OWNER='***' AIRFLOW_CTX_DAG_ID='practice_etl_pipeline' AIRFLOW_CTX_TASK_ID='transform_and_load' AIRFLOW_CTX_EXECUTION_DATE='2025-07-05T12:09:20.312632+00:00' AIRFLOW_CTX_TRY_NUMBER='1' AIRFLOW_CTX_DAG_RUN_ID='manual__2025-07-05T12:09:20.312632+00:00'
[2025-07-05T12:09:28.656+0000] {taskinstance.py:430} INFO - ::endgroup::
[2025-07-05T12:09:28.772+0000] {taskinstance.py:441} INFO - ::group::Post task execution logs
[2025-07-05T12:09:28.772+0000] {taskinstance.py:2905} ERROR - Task failed with exception
Traceback (most recent call last):
  File "/home/airflow/.local/lib/python3.12/site-packages/airflow/models/taskinstance.py", line 465, in _execute_task
    result = _execute_callable(context=context, **execute_callable_kwargs)
             ^^^^^^^^^^^^^^^^^^^^^^^^^^^^^^^^^^^^^^^^^^^^^^^^^^^^^^^^^^^^^
  File "/home/airflow/.local/lib/python3.12/site-packages/airflow/models/taskinstance.py", line 432, in _execute_callable
    return execute_callable(context=context, **execute_callable_kwargs)
           ^^^^^^^^^^^^^^^^^^^^^^^^^^^^^^^^^^^^^^^^^^^^^^^^^^^^^^^^^^^^
  File "/home/airflow/.local/lib/python3.12/site-packages/airflow/models/baseoperator.py", line 401, in wrapper
    return func(self, *args, **kwargs)
           ^^^^^^^^^^^^^^^^^^^^^^^^^^^
  File "/home/airflow/.local/lib/python3.12/site-packages/airflow/operators/python.py", line 235, in execute
    return_value = self.execute_callable()
                   ^^^^^^^^^^^^^^^^^^^^^^^
  File "/home/airflow/.local/lib/python3.12/site-packages/airflow/operators/python.py", line 252, in execute_callable
    return self.python_callable(*self.op_args, **self.op_kwargs)
           ^^^^^^^^^^^^^^^^^^^^^^^^^^^^^^^^^^^^^^^^^^^^^^^^^^^^^
  File "/opt/airflow/dags/main.py", line 104, in transform_and_load
    df = spark.read.csv(CSV_PATH + file).distinct()
         ^^^^^^^^^^^^^^^^^^^^^^^^^^^^^^^
  File "/home/airflow/.local/lib/python3.12/site-packages/pyspark/sql/readwriter.py", line 838, in csv
    return self._df(self._jreader.csv(self._spark._sc._jvm.PythonUtils.toSeq(path)))
                    ^^^^^^^^^^^^^^^^^^^^^^^^^^^^^^^^^^^^^^^^^^^^^^^^^^^^^^^^^^^^^^^
  File "/opt/spark/spark-4.0.0-bin-hadoop3/python/lib/py4j-0.10.9.9-src.zip/py4j/java_gateway.py", line 1362, in __call__
    return_value = get_return_value(
                   ^^^^^^^^^^^^^^^^^
  File "/home/airflow/.local/lib/python3.12/site-packages/pyspark/errors/exceptions/captured.py", line 288, in deco
    raise converted from None
pyspark.errors.exceptions.captured.AnalysisException: [PATH_NOT_FOUND] Path does not exist: file:/opt/airflow/dags/filesft_balance_f.csv. SQLSTATE: 42K03
[2025-07-05T12:09:28.782+0000] {taskinstance.py:1206} INFO - Marking task as FAILED. dag_id=practice_etl_pipeline, task_id=transform_and_load, run_id=manual__2025-07-05T12:09:20.312632+00:00, execution_date=20250705T120920, start_date=20250705T120928, end_date=20250705T120928
[2025-07-05T12:09:28.790+0000] {standard_task_runner.py:110} ERROR - Failed to execute job 46 for task transform_and_load ([PATH_NOT_FOUND] Path does not exist: file:/opt/airflow/dags/filesft_balance_f.csv. SQLSTATE: 42K03; 9052)
[2025-07-05T12:09:28.828+0000] {local_task_job_runner.py:240} INFO - Task exited with return code 1
[2025-07-05T12:09:28.834+0000] {local_task_job_runner.py:222} INFO - ::endgroup::
