[2025-07-05T13:49:30.418+0000] {local_task_job_runner.py:120} INFO - ::group::Pre task execution logs
[2025-07-05T13:49:30.429+0000] {taskinstance.py:2076} INFO - Dependencies all met for dep_context=non-requeueable deps ti=<TaskInstance: practice_etl_pipeline.load_log_data manual__2025-07-05T13:48:22.799260+00:00 [queued]>
[2025-07-05T13:49:30.433+0000] {taskinstance.py:2076} INFO - Dependencies all met for dep_context=requeueable deps ti=<TaskInstance: practice_etl_pipeline.load_log_data manual__2025-07-05T13:48:22.799260+00:00 [queued]>
[2025-07-05T13:49:30.434+0000] {taskinstance.py:2306} INFO - Starting attempt 1 of 1
[2025-07-05T13:49:30.441+0000] {taskinstance.py:2330} INFO - Executing <Task(PythonOperator): load_log_data> on 2025-07-05 13:48:22.799260+00:00
[2025-07-05T13:49:30.445+0000] {clientserver.py:570} INFO - Closing down clientserver connection
[2025-07-05T13:49:30.445+0000] {warnings.py:112} WARNING - /home/***/.local/lib/python3.12/site-packages/***/task/task_runner/standard_task_runner.py:61: DeprecationWarning: This process (pid=7439) is multi-threaded, use of fork() may lead to deadlocks in the child.
  pid = os.fork()

[2025-07-05T13:49:30.446+0000] {standard_task_runner.py:63} INFO - Started process 7579 to run task
[2025-07-05T13:49:30.447+0000] {standard_task_runner.py:90} INFO - Running: ['***', 'tasks', 'run', 'practice_etl_pipeline', 'load_log_data', 'manual__2025-07-05T13:48:22.799260+00:00', '--job-id', '123', '--raw', '--subdir', 'DAGS_FOLDER/main.py', '--cfg-path', '/tmp/tmp2zypogmt']
[2025-07-05T13:49:30.448+0000] {standard_task_runner.py:91} INFO - Job 123: Subtask load_log_data
[2025-07-05T13:49:30.480+0000] {task_command.py:426} INFO - Running <TaskInstance: practice_etl_pipeline.load_log_data manual__2025-07-05T13:48:22.799260+00:00 [running]> on host 93b0937d74ff
[2025-07-05T13:49:30.526+0000] {taskinstance.py:2648} INFO - Exporting env vars: AIRFLOW_CTX_DAG_OWNER='***' AIRFLOW_CTX_DAG_ID='practice_etl_pipeline' AIRFLOW_CTX_TASK_ID='load_log_data' AIRFLOW_CTX_EXECUTION_DATE='2025-07-05T13:48:22.799260+00:00' AIRFLOW_CTX_TRY_NUMBER='1' AIRFLOW_CTX_DAG_RUN_ID='manual__2025-07-05T13:48:22.799260+00:00'
[2025-07-05T13:49:30.527+0000] {taskinstance.py:430} INFO - ::endgroup::
[2025-07-05T13:49:31.041+0000] {clientserver.py:529} INFO - Error while sending or receiving.
Traceback (most recent call last):
  File "/opt/spark/spark-4.0.0-bin-hadoop3/python/lib/py4j-0.10.9.9-src.zip/py4j/clientserver.py", line 527, in send_command
    self.socket.sendall(command.encode("utf-8"))
ConnectionResetError: [Errno 104] Connection reset by peer
[2025-07-05T13:49:31.042+0000] {clientserver.py:570} INFO - Closing down clientserver connection
[2025-07-05T13:49:31.043+0000] {java_gateway.py:1056} INFO - Exception while sending command.
Traceback (most recent call last):
  File "/opt/spark/spark-4.0.0-bin-hadoop3/python/lib/py4j-0.10.9.9-src.zip/py4j/clientserver.py", line 527, in send_command
    self.socket.sendall(command.encode("utf-8"))
ConnectionResetError: [Errno 104] Connection reset by peer

During handling of the above exception, another exception occurred:

Traceback (most recent call last):
  File "/opt/spark/spark-4.0.0-bin-hadoop3/python/lib/py4j-0.10.9.9-src.zip/py4j/java_gateway.py", line 1038, in send_command
    response = connection.send_command(command)
               ^^^^^^^^^^^^^^^^^^^^^^^^^^^^^^^^
  File "/opt/spark/spark-4.0.0-bin-hadoop3/python/lib/py4j-0.10.9.9-src.zip/py4j/clientserver.py", line 530, in send_command
    raise Py4JNetworkError(
py4j.protocol.Py4JNetworkError: Error while sending
[2025-07-05T13:49:31.044+0000] {clientserver.py:570} INFO - Closing down clientserver connection
[2025-07-05T13:49:31.860+0000] {logging_mixin.py:188} INFO - +---------+------+-------+-------+
|timestamp|status|message|obj_num|
+---------+------+-------+-------+
+---------+------+-------+-------+
