[2025-07-05T21:35:26.404+0000] {local_task_job_runner.py:120} INFO - ::group::Pre task execution logs
[2025-07-05T21:35:26.415+0000] {taskinstance.py:2076} INFO - Dependencies all met for dep_context=non-requeueable deps ti=<TaskInstance: practice_etl_pipeline.transform_and_load manual__2025-07-05T21:35:16.063559+00:00 [queued]>
[2025-07-05T21:35:26.420+0000] {taskinstance.py:2076} INFO - Dependencies all met for dep_context=requeueable deps ti=<TaskInstance: practice_etl_pipeline.transform_and_load manual__2025-07-05T21:35:16.063559+00:00 [queued]>
[2025-07-05T21:35:26.420+0000] {taskinstance.py:2306} INFO - Starting attempt 1 of 1
[2025-07-05T21:35:26.428+0000] {taskinstance.py:2330} INFO - Executing <Task(PythonOperator): transform_and_load> on 2025-07-05 21:35:16.063559+00:00
[2025-07-05T21:35:26.431+0000] {clientserver.py:570} INFO - Closing down clientserver connection
[2025-07-05T21:35:26.432+0000] {warnings.py:112} WARNING - /home/***/.local/lib/python3.12/site-packages/***/task/task_runner/standard_task_runner.py:61: DeprecationWarning: This process (pid=246) is multi-threaded, use of fork() may lead to deadlocks in the child.
  pid = os.fork()

[2025-07-05T21:35:26.433+0000] {standard_task_runner.py:63} INFO - Started process 385 to run task
[2025-07-05T21:35:26.434+0000] {standard_task_runner.py:90} INFO - Running: ['***', 'tasks', 'run', 'practice_etl_pipeline', 'transform_and_load', 'manual__2025-07-05T21:35:16.063559+00:00', '--job-id', '249', '--raw', '--subdir', 'DAGS_FOLDER/main.py', '--cfg-path', '/tmp/tmpgg4ma80p']
[2025-07-05T21:35:26.435+0000] {standard_task_runner.py:91} INFO - Job 249: Subtask transform_and_load
[2025-07-05T21:35:26.512+0000] {task_command.py:426} INFO - Running <TaskInstance: practice_etl_pipeline.transform_and_load manual__2025-07-05T21:35:16.063559+00:00 [running]> on host 93b0937d74ff
[2025-07-05T21:35:26.563+0000] {taskinstance.py:2648} INFO - Exporting env vars: AIRFLOW_CTX_DAG_OWNER='***' AIRFLOW_CTX_DAG_ID='practice_etl_pipeline' AIRFLOW_CTX_TASK_ID='transform_and_load' AIRFLOW_CTX_EXECUTION_DATE='2025-07-05T21:35:16.063559+00:00' AIRFLOW_CTX_TRY_NUMBER='1' AIRFLOW_CTX_DAG_RUN_ID='manual__2025-07-05T21:35:16.063559+00:00'
[2025-07-05T21:35:26.564+0000] {taskinstance.py:430} INFO - ::endgroup::
[2025-07-05T21:35:27.812+0000] {logging_mixin.py:188} INFO - +----------+
|on_date   |
+----------+
|31.12.2017|
|31.12.2017|
|31.12.2017|
|31.12.2017|
|31.12.2017|
+----------+
only showing top 5 rows
[2025-07-05T21:35:28.090+0000] {taskinstance.py:441} INFO - ::group::Post task execution logs
[2025-07-05T21:35:28.090+0000] {taskinstance.py:2905} ERROR - Task failed with exception
Traceback (most recent call last):
  File "/home/airflow/.local/lib/python3.12/site-packages/airflow/models/taskinstance.py", line 465, in _execute_task
    result = _execute_callable(context=context, **execute_callable_kwargs)
             ^^^^^^^^^^^^^^^^^^^^^^^^^^^^^^^^^^^^^^^^^^^^^^^^^^^^^^^^^^^^^
  File "/home/airflow/.local/lib/python3.12/site-packages/airflow/models/taskinstance.py", line 432, in _execute_callable
    return execute_callable(context=context, **execute_callable_kwargs)
           ^^^^^^^^^^^^^^^^^^^^^^^^^^^^^^^^^^^^^^^^^^^^^^^^^^^^^^^^^^^^
  File "/home/airflow/.local/lib/python3.12/site-packages/airflow/models/baseoperator.py", line 401, in wrapper
    return func(self, *args, **kwargs)
           ^^^^^^^^^^^^^^^^^^^^^^^^^^^
  File "/home/airflow/.local/lib/python3.12/site-packages/airflow/operators/python.py", line 235, in execute
    return_value = self.execute_callable()
                   ^^^^^^^^^^^^^^^^^^^^^^^
  File "/home/airflow/.local/lib/python3.12/site-packages/airflow/operators/python.py", line 252, in execute_callable
    return self.python_callable(*self.op_args, **self.op_kwargs)
           ^^^^^^^^^^^^^^^^^^^^^^^^^^^^^^^^^^^^^^^^^^^^^^^^^^^^^
  File "/opt/airflow/dags/main.py", line 220, in transform_and_load
    df = convert_date_columns(df)
         ^^^^^^^^^^^^^^^^^^^^^^^^
  File "/opt/airflow/dags/main.py", line 149, in convert_date_columns
    df.select(col_name).show(5, truncate=False)
  File "/home/airflow/.local/lib/python3.12/site-packages/pyspark/sql/classic/dataframe.py", line 285, in show
    print(self._show_string(n, truncate, vertical))
          ^^^^^^^^^^^^^^^^^^^^^^^^^^^^^^^^^^^^^^^^
  File "/home/airflow/.local/lib/python3.12/site-packages/pyspark/sql/classic/dataframe.py", line 316, in _show_string
    return self._jdf.showString(n, int_truncate, vertical)
           ^^^^^^^^^^^^^^^^^^^^^^^^^^^^^^^^^^^^^^^^^^^^^^^
  File "/opt/spark/spark-4.0.0-bin-hadoop3/python/lib/py4j-0.10.9.9-src.zip/py4j/java_gateway.py", line 1362, in __call__
    return_value = get_return_value(
                   ^^^^^^^^^^^^^^^^^
  File "/home/airflow/.local/lib/python3.12/site-packages/pyspark/errors/exceptions/captured.py", line 288, in deco
    raise converted from None
pyspark.errors.exceptions.captured.DateTimeException: [CANNOT_PARSE_TIMESTAMP] Text '31.12.2017' could not be parsed, unparsed text found at index 2. Use `try_to_date` to tolerate invalid input string and return NULL instead. SQLSTATE: 22007
[2025-07-05T21:35:28.100+0000] {taskinstance.py:1206} INFO - Marking task as FAILED. dag_id=practice_etl_pipeline, task_id=transform_and_load, run_id=manual__2025-07-05T21:35:16.063559+00:00, execution_date=20250705T213516, start_date=20250705T213526, end_date=20250705T213528
[2025-07-05T21:35:28.109+0000] {standard_task_runner.py:110} ERROR - Failed to execute job 249 for task transform_and_load ([CANNOT_PARSE_TIMESTAMP] Text '31.12.2017' could not be parsed, unparsed text found at index 2. Use `try_to_date` to tolerate invalid input string and return NULL instead. SQLSTATE: 22007; 385)
[2025-07-05T21:35:28.130+0000] {local_task_job_runner.py:240} INFO - Task exited with return code 1
[2025-07-05T21:35:28.139+0000] {taskinstance.py:3503} INFO - 0 downstream tasks scheduled from follow-on schedule check
[2025-07-05T21:35:28.142+0000] {local_task_job_runner.py:222} INFO - ::endgroup::
